2018-05-04 18:05:57,779 ERROR: Unhandled exception [in ./app/tasks.py:65]
Traceback (most recent call last):
  File "./app/tasks.py", line 58, in export_posts
    text_body=render_template('email/export_posts.txt', user=user),
  File "/Users/kadakia/anaconda3/lib/python3.6/site-packages/flask/templating.py", line 133, in render_template
    return _render(ctx.app.jinja_env.get_or_select_template(template_name_or_list),
  File "/Users/kadakia/anaconda3/lib/python3.6/site-packages/jinja2/environment.py", line 869, in get_or_select_template
    return self.get_template(template_name_or_list, parent, globals)
  File "/Users/kadakia/anaconda3/lib/python3.6/site-packages/jinja2/environment.py", line 830, in get_template
    return self._load_template(name, self.make_globals(globals))
  File "/Users/kadakia/anaconda3/lib/python3.6/site-packages/jinja2/environment.py", line 804, in _load_template
    template = self.loader.load(self, name, globals)
  File "/Users/kadakia/anaconda3/lib/python3.6/site-packages/jinja2/loaders.py", line 113, in load
    source, filename, uptodate = self.get_source(environment, name)
  File "/Users/kadakia/anaconda3/lib/python3.6/site-packages/flask/templating.py", line 57, in get_source
    return self._get_source_fast(environment, template)
  File "/Users/kadakia/anaconda3/lib/python3.6/site-packages/flask/templating.py", line 85, in _get_source_fast
    raise TemplateNotFound(template)
jinja2.exceptions.TemplateNotFound: email/export_posts.txt
2018-05-04 18:08:44,017 INFO: RohanApp startup [in ./app/__init__.py:82]
2018-05-04 18:09:19,166 ERROR: Unhandled exception [in ./app/tasks.py:65]
Traceback (most recent call last):
  File "./app/tasks.py", line 58, in export_posts
    text_body=render_template('email/export_posts.txt', user=user),
  File "/Users/kadakia/anaconda3/lib/python3.6/site-packages/flask/templating.py", line 133, in render_template
    return _render(ctx.app.jinja_env.get_or_select_template(template_name_or_list),
  File "/Users/kadakia/anaconda3/lib/python3.6/site-packages/jinja2/environment.py", line 869, in get_or_select_template
    return self.get_template(template_name_or_list, parent, globals)
  File "/Users/kadakia/anaconda3/lib/python3.6/site-packages/jinja2/environment.py", line 830, in get_template
    return self._load_template(name, self.make_globals(globals))
  File "/Users/kadakia/anaconda3/lib/python3.6/site-packages/jinja2/environment.py", line 804, in _load_template
    template = self.loader.load(self, name, globals)
  File "/Users/kadakia/anaconda3/lib/python3.6/site-packages/jinja2/loaders.py", line 113, in load
    source, filename, uptodate = self.get_source(environment, name)
  File "/Users/kadakia/anaconda3/lib/python3.6/site-packages/flask/templating.py", line 57, in get_source
    return self._get_source_fast(environment, template)
  File "/Users/kadakia/anaconda3/lib/python3.6/site-packages/flask/templating.py", line 85, in _get_source_fast
    raise TemplateNotFound(template)
jinja2.exceptions.TemplateNotFound: email/export_posts.txt
2018-05-04 18:13:33,423 INFO: RohanApp startup [in ./app/__init__.py:82]
2018-05-04 18:13:48,589 ERROR: Unhandled exception [in ./app/tasks.py:65]
Traceback (most recent call last):
  File "/Users/kadakia/anaconda3/lib/python3.6/site-packages/flask_mail.py", line 492, in send
    message.send(connection)
  File "/Users/kadakia/anaconda3/lib/python3.6/site-packages/flask_mail.py", line 427, in send
    connection.send(self)
  File "/Users/kadakia/anaconda3/lib/python3.6/site-packages/flask_mail.py", line 192, in send
    message.rcpt_options)
  File "/Users/kadakia/anaconda3/lib/python3.6/smtplib.py", line 852, in sendmail
    self.ehlo_or_helo_if_needed()
  File "/Users/kadakia/anaconda3/lib/python3.6/smtplib.py", line 600, in ehlo_or_helo_if_needed
    if not (200 <= self.ehlo()[0] <= 299):
  File "/Users/kadakia/anaconda3/lib/python3.6/smtplib.py", line 440, in ehlo
    self.putcmd(self.ehlo_msg, name or self.local_hostname)
  File "/Users/kadakia/anaconda3/lib/python3.6/smtplib.py", line 367, in putcmd
    self.send(str)
  File "/Users/kadakia/anaconda3/lib/python3.6/smtplib.py", line 359, in send
    raise SMTPServerDisconnected('please run connect() first')
smtplib.SMTPServerDisconnected: please run connect() first

During handling of the above exception, another exception occurred:

Traceback (most recent call last):
  File "./app/tasks.py", line 61, in export_posts
    sync=True) # why are we sending this synchronously?
  File "./app/email.py", line 19, in send_email
    mail.send(msg)
  File "/Users/kadakia/anaconda3/lib/python3.6/site-packages/flask_mail.py", line 492, in send
    message.send(connection)
  File "/Users/kadakia/anaconda3/lib/python3.6/site-packages/flask_mail.py", line 152, in __exit__
    self.host.quit()
  File "/Users/kadakia/anaconda3/lib/python3.6/smtplib.py", line 983, in quit
    res = self.docmd("quit")
  File "/Users/kadakia/anaconda3/lib/python3.6/smtplib.py", line 420, in docmd
    self.putcmd(cmd, args)
  File "/Users/kadakia/anaconda3/lib/python3.6/smtplib.py", line 367, in putcmd
    self.send(str)
  File "/Users/kadakia/anaconda3/lib/python3.6/smtplib.py", line 359, in send
    raise SMTPServerDisconnected('please run connect() first')
smtplib.SMTPServerDisconnected: please run connect() first
2018-05-04 18:18:00,898 INFO: RohanApp startup [in ./app/__init__.py:82]
2018-05-04 20:51:45,852 INFO: RohanApp startup [in ./app/__init__.py:82]
2018-05-06 22:26:35,966 INFO: RohanApp startup [in ./app/__init__.py:82]
2018-05-11 14:02:07,415 INFO: RohanApp startup [in ./app/__init__.py:97]
2018-05-19 20:06:50,142 INFO: RohanApp startup [in /Users/kadakia/rohanapp/app/__init__.py:98]
2018-05-29 22:44:25,474 INFO: RohanApp startup [in /Users/kadakia/rohanapp/app/__init__.py:101]
2018-05-29 22:47:16,949 INFO: RohanApp startup [in /Users/kadakia/rohanapp/app/__init__.py:101]
2018-05-29 22:50:36,402 ERROR: Exception on /api/users [GET] [in /Users/kadakia/anaconda3/lib/python3.6/site-packages/flask/app.py:1560]
Traceback (most recent call last):
  File "/Users/kadakia/anaconda3/lib/python3.6/site-packages/flask/app.py", line 1982, in wsgi_app
    response = self.full_dispatch_request()
  File "/Users/kadakia/anaconda3/lib/python3.6/site-packages/flask/app.py", line 1615, in full_dispatch_request
    return self.finalize_request(rv)
  File "/Users/kadakia/anaconda3/lib/python3.6/site-packages/flask/app.py", line 1630, in finalize_request
    response = self.make_response(rv)
  File "/Users/kadakia/anaconda3/lib/python3.6/site-packages/flask/app.py", line 1725, in make_response
    raise ValueError('View function did not return a response')
ValueError: View function did not return a response
2018-05-29 22:50:55,081 INFO: RohanApp startup [in /Users/kadakia/rohanapp/app/__init__.py:101]
2018-05-29 23:07:29,141 INFO: RohanApp startup [in /Users/kadakia/rohanapp/app/__init__.py:101]
2018-05-29 23:09:36,070 INFO: RohanApp startup [in /Users/kadakia/rohanapp/app/__init__.py:101]
2018-05-29 23:25:40,632 INFO: RohanApp startup [in /Users/kadakia/rohanapp/app/__init__.py:101]
