2018-04-14 12:52:53,222 ERROR: Exception on /index [GET] [in /Users/kadakia/anaconda3/lib/python3.6/site-packages/flask/app.py:1560]
Traceback (most recent call last):
  File "/Users/kadakia/anaconda3/lib/python3.6/site-packages/flask/app.py", line 1982, in wsgi_app
    response = self.full_dispatch_request()
  File "/Users/kadakia/anaconda3/lib/python3.6/site-packages/flask/app.py", line 1614, in full_dispatch_request
    rv = self.handle_user_exception(e)
  File "/Users/kadakia/anaconda3/lib/python3.6/site-packages/flask/app.py", line 1517, in handle_user_exception
    reraise(exc_type, exc_value, tb)
  File "/Users/kadakia/anaconda3/lib/python3.6/site-packages/flask/_compat.py", line 33, in reraise
    raise value
  File "/Users/kadakia/anaconda3/lib/python3.6/site-packages/flask/app.py", line 1610, in full_dispatch_request
    rv = self.preprocess_request()
  File "/Users/kadakia/anaconda3/lib/python3.6/site-packages/flask/app.py", line 1831, in preprocess_request
    rv = func()
  File "/Users/kadakia/flask_app/app/routes.py", line 84, in before_request
    if current_user.is_authenticated:
  File "/Users/kadakia/anaconda3/lib/python3.6/site-packages/werkzeug/local.py", line 347, in __getattr__
    return getattr(self._get_current_object(), name)
  File "/Users/kadakia/anaconda3/lib/python3.6/site-packages/werkzeug/local.py", line 306, in _get_current_object
    return self.__local()
  File "/Users/kadakia/anaconda3/lib/python3.6/site-packages/flask_login/utils.py", line 26, in <lambda>
    current_user = LocalProxy(lambda: _get_user())
  File "/Users/kadakia/anaconda3/lib/python3.6/site-packages/flask_login/utils.py", line 335, in _get_user
    current_app.login_manager._load_user()
  File "/Users/kadakia/anaconda3/lib/python3.6/site-packages/flask_login/login_manager.py", line 359, in _load_user
    return self.reload_user()
  File "/Users/kadakia/anaconda3/lib/python3.6/site-packages/flask_login/login_manager.py", line 321, in reload_user
    user = self.user_callback(user_id)
  File "/Users/kadakia/flask_app/app/models.py", line 91, in load_user
    return User.query.get(int(id))
  File "/Users/kadakia/anaconda3/lib/python3.6/site-packages/sqlalchemy/orm/query.py", line 871, in get
    ident, loading.load_on_ident)
  File "/Users/kadakia/anaconda3/lib/python3.6/site-packages/sqlalchemy/orm/query.py", line 905, in _get_impl
    return fallback_fn(self, key)
  File "/Users/kadakia/anaconda3/lib/python3.6/site-packages/sqlalchemy/orm/loading.py", line 231, in load_on_ident
    return q.one()
  File "/Users/kadakia/anaconda3/lib/python3.6/site-packages/sqlalchemy/orm/query.py", line 2837, in one
    ret = self.one_or_none()
  File "/Users/kadakia/anaconda3/lib/python3.6/site-packages/sqlalchemy/orm/query.py", line 2807, in one_or_none
    ret = list(self)
  File "/Users/kadakia/anaconda3/lib/python3.6/site-packages/sqlalchemy/orm/loading.py", line 97, in instances
    util.raise_from_cause(err)
  File "/Users/kadakia/anaconda3/lib/python3.6/site-packages/sqlalchemy/util/compat.py", line 203, in raise_from_cause
    reraise(type(exception), exception, tb=exc_tb, cause=cause)
  File "/Users/kadakia/anaconda3/lib/python3.6/site-packages/sqlalchemy/util/compat.py", line 187, in reraise
    raise value
  File "/Users/kadakia/anaconda3/lib/python3.6/site-packages/sqlalchemy/orm/loading.py", line 78, in instances
    rows = [proc(row) for row in fetch]
  File "/Users/kadakia/anaconda3/lib/python3.6/site-packages/sqlalchemy/orm/loading.py", line 78, in <listcomp>
    rows = [proc(row) for row in fetch]
  File "/Users/kadakia/anaconda3/lib/python3.6/site-packages/sqlalchemy/orm/loading.py", line 492, in _instance
    loaded_instance, populate_existing, populators)
  File "/Users/kadakia/anaconda3/lib/python3.6/site-packages/sqlalchemy/orm/loading.py", line 592, in _populate_full
    dict_[key] = getter(row)
ValueError: Couldn't parse datetime string: '04/14/2018 04:06:17 PM'
2018-04-14 12:53:05,671 ERROR: Exception on /login [GET] [in /Users/kadakia/anaconda3/lib/python3.6/site-packages/flask/app.py:1560]
Traceback (most recent call last):
  File "/Users/kadakia/anaconda3/lib/python3.6/site-packages/flask/app.py", line 1982, in wsgi_app
    response = self.full_dispatch_request()
  File "/Users/kadakia/anaconda3/lib/python3.6/site-packages/flask/app.py", line 1614, in full_dispatch_request
    rv = self.handle_user_exception(e)
  File "/Users/kadakia/anaconda3/lib/python3.6/site-packages/flask/app.py", line 1517, in handle_user_exception
    reraise(exc_type, exc_value, tb)
  File "/Users/kadakia/anaconda3/lib/python3.6/site-packages/flask/_compat.py", line 33, in reraise
    raise value
  File "/Users/kadakia/anaconda3/lib/python3.6/site-packages/flask/app.py", line 1610, in full_dispatch_request
    rv = self.preprocess_request()
  File "/Users/kadakia/anaconda3/lib/python3.6/site-packages/flask/app.py", line 1831, in preprocess_request
    rv = func()
  File "/Users/kadakia/flask_app/app/routes.py", line 84, in before_request
    if current_user.is_authenticated:
  File "/Users/kadakia/anaconda3/lib/python3.6/site-packages/werkzeug/local.py", line 347, in __getattr__
    return getattr(self._get_current_object(), name)
  File "/Users/kadakia/anaconda3/lib/python3.6/site-packages/werkzeug/local.py", line 306, in _get_current_object
    return self.__local()
  File "/Users/kadakia/anaconda3/lib/python3.6/site-packages/flask_login/utils.py", line 26, in <lambda>
    current_user = LocalProxy(lambda: _get_user())
  File "/Users/kadakia/anaconda3/lib/python3.6/site-packages/flask_login/utils.py", line 335, in _get_user
    current_app.login_manager._load_user()
  File "/Users/kadakia/anaconda3/lib/python3.6/site-packages/flask_login/login_manager.py", line 359, in _load_user
    return self.reload_user()
  File "/Users/kadakia/anaconda3/lib/python3.6/site-packages/flask_login/login_manager.py", line 321, in reload_user
    user = self.user_callback(user_id)
  File "/Users/kadakia/flask_app/app/models.py", line 91, in load_user
    return User.query.get(int(id))
  File "/Users/kadakia/anaconda3/lib/python3.6/site-packages/sqlalchemy/orm/query.py", line 871, in get
    ident, loading.load_on_ident)
  File "/Users/kadakia/anaconda3/lib/python3.6/site-packages/sqlalchemy/orm/query.py", line 905, in _get_impl
    return fallback_fn(self, key)
  File "/Users/kadakia/anaconda3/lib/python3.6/site-packages/sqlalchemy/orm/loading.py", line 231, in load_on_ident
    return q.one()
  File "/Users/kadakia/anaconda3/lib/python3.6/site-packages/sqlalchemy/orm/query.py", line 2837, in one
    ret = self.one_or_none()
  File "/Users/kadakia/anaconda3/lib/python3.6/site-packages/sqlalchemy/orm/query.py", line 2807, in one_or_none
    ret = list(self)
  File "/Users/kadakia/anaconda3/lib/python3.6/site-packages/sqlalchemy/orm/loading.py", line 97, in instances
    util.raise_from_cause(err)
  File "/Users/kadakia/anaconda3/lib/python3.6/site-packages/sqlalchemy/util/compat.py", line 203, in raise_from_cause
    reraise(type(exception), exception, tb=exc_tb, cause=cause)
  File "/Users/kadakia/anaconda3/lib/python3.6/site-packages/sqlalchemy/util/compat.py", line 187, in reraise
    raise value
  File "/Users/kadakia/anaconda3/lib/python3.6/site-packages/sqlalchemy/orm/loading.py", line 78, in instances
    rows = [proc(row) for row in fetch]
  File "/Users/kadakia/anaconda3/lib/python3.6/site-packages/sqlalchemy/orm/loading.py", line 78, in <listcomp>
    rows = [proc(row) for row in fetch]
  File "/Users/kadakia/anaconda3/lib/python3.6/site-packages/sqlalchemy/orm/loading.py", line 492, in _instance
    loaded_instance, populate_existing, populators)
  File "/Users/kadakia/anaconda3/lib/python3.6/site-packages/sqlalchemy/orm/loading.py", line 592, in _populate_full
    dict_[key] = getter(row)
ValueError: Couldn't parse datetime string: '04/14/2018 04:06:17 PM'
