2018-04-09 20:27:51,285 INFO: RohanApp startup [in /Users/kadakia/flask_app/app/__init__.py:45]
2018-04-09 20:31:24,432 INFO: RohanApp startup [in /Users/kadakia/flask_app/app/__init__.py:45]
2018-04-09 20:32:11,322 INFO: RohanApp startup [in /Users/kadakia/flask_app/app/__init__.py:45]
2018-04-09 20:36:10,319 INFO: RohanApp startup [in /Users/kadakia/flask_app/app/__init__.py:45]
2018-04-09 20:39:25,114 INFO: RohanApp startup [in /Users/kadakia/flask_app/app/__init__.py:45]
2018-04-09 20:56:50,779 INFO: RohanApp startup [in /Users/kadakia/flask_app/app/__init__.py:45]
2018-04-09 20:58:53,042 INFO: RohanApp startup [in /Users/kadakia/flask_app/app/__init__.py:45]
2018-04-10 17:37:24,247 INFO: RohanApp startup [in /Users/kadakia/flask_app/app/__init__.py:45]
2018-04-10 17:37:48,173 INFO: RohanApp startup [in /Users/kadakia/flask_app/app/__init__.py:45]
2018-04-10 18:40:07,594 INFO: RohanApp startup [in /Users/kadakia/flask_app/app/__init__.py:45]
2018-04-10 18:40:27,829 INFO: RohanApp startup [in /Users/kadakia/flask_app/app/__init__.py:45]
2018-04-10 18:40:48,222 INFO: RohanApp startup [in /Users/kadakia/flask_app/app/__init__.py:45]
2018-04-10 19:13:48,694 INFO: RohanApp startup [in /Users/kadakia/flask_app/app/__init__.py:45]
2018-04-10 19:16:23,628 INFO: RohanApp startup [in /Users/kadakia/flask_app/app/__init__.py:45]
2018-04-10 19:22:55,473 INFO: RohanApp startup [in /Users/kadakia/flask_app/app/__init__.py:45]
2018-04-10 19:24:30,192 INFO: RohanApp startup [in /Users/kadakia/flask_app/app/__init__.py:45]
2018-04-10 19:25:53,918 INFO: RohanApp startup [in /Users/kadakia/flask_app/app/__init__.py:45]
2018-04-11 00:14:23,618 INFO: RohanApp startup [in /Users/kadakia/flask_app/app/__init__.py:45]
2018-04-11 00:18:01,259 INFO: RohanApp startup [in /Users/kadakia/flask_app/app/__init__.py:45]
2018-04-11 00:21:27,089 INFO: RohanApp startup [in /Users/kadakia/flask_app/app/__init__.py:45]
2018-04-11 00:24:21,106 INFO: RohanApp startup [in /Users/kadakia/flask_app/app/__init__.py:45]
2018-04-11 00:34:38,016 INFO: RohanApp startup [in /Users/kadakia/flask_app/app/__init__.py:45]
2018-04-11 00:45:08,440 INFO: RohanApp startup [in /Users/kadakia/flask_app/app/__init__.py:45]
2018-04-11 00:51:13,126 INFO: RohanApp startup [in /Users/kadakia/flask_app/app/__init__.py:45]
2018-04-11 00:59:45,147 INFO: RohanApp startup [in /Users/kadakia/flask_app/app/__init__.py:45]
2018-04-11 01:01:40,066 INFO: RohanApp startup [in /Users/kadakia/flask_app/app/__init__.py:45]
2018-04-11 21:25:55,681 INFO: RohanApp startup [in /Users/kadakia/flask_app/app/__init__.py:45]
2018-04-11 21:53:09,424 INFO: RohanApp startup [in /Users/kadakia/flask_app/app/__init__.py:45]
2018-04-11 21:53:15,162 ERROR: Exception on /index [GET] [in /Users/kadakia/anaconda3/lib/python3.6/site-packages/flask/app.py:1560]
Traceback (most recent call last):
  File "/Users/kadakia/anaconda3/lib/python3.6/site-packages/flask/app.py", line 1982, in wsgi_app
    response = self.full_dispatch_request()
  File "/Users/kadakia/anaconda3/lib/python3.6/site-packages/flask/app.py", line 1614, in full_dispatch_request
    rv = self.handle_user_exception(e)
  File "/Users/kadakia/anaconda3/lib/python3.6/site-packages/flask/app.py", line 1517, in handle_user_exception
    reraise(exc_type, exc_value, tb)
  File "/Users/kadakia/anaconda3/lib/python3.6/site-packages/flask/_compat.py", line 33, in reraise
    raise value
  File "/Users/kadakia/anaconda3/lib/python3.6/site-packages/flask/app.py", line 1612, in full_dispatch_request
    rv = self.dispatch_request()
  File "/Users/kadakia/anaconda3/lib/python3.6/site-packages/flask/app.py", line 1598, in dispatch_request
    return self.view_functions[rule.endpoint](**req.view_args)
  File "/Users/kadakia/anaconda3/lib/python3.6/site-packages/flask_login/utils.py", line 261, in decorated_view
    return func(*args, **kwargs)
  File "/Users/kadakia/flask_app/app/routes.py", line 32, in index
    next_url = next_url, prev_url = prev_url)
UnboundLocalError: local variable 'prev_url' referenced before assignment
2018-04-11 22:05:13,470 INFO: RohanApp startup [in /Users/kadakia/flask_app/app/__init__.py:45]
2018-04-11 22:05:16,759 ERROR: Exception on /index [GET] [in /Users/kadakia/anaconda3/lib/python3.6/site-packages/flask/app.py:1560]
Traceback (most recent call last):
  File "/Users/kadakia/anaconda3/lib/python3.6/site-packages/flask/app.py", line 1982, in wsgi_app
    response = self.full_dispatch_request()
  File "/Users/kadakia/anaconda3/lib/python3.6/site-packages/flask/app.py", line 1614, in full_dispatch_request
    rv = self.handle_user_exception(e)
  File "/Users/kadakia/anaconda3/lib/python3.6/site-packages/flask/app.py", line 1517, in handle_user_exception
    reraise(exc_type, exc_value, tb)
  File "/Users/kadakia/anaconda3/lib/python3.6/site-packages/flask/_compat.py", line 33, in reraise
    raise value
  File "/Users/kadakia/anaconda3/lib/python3.6/site-packages/flask/app.py", line 1612, in full_dispatch_request
    rv = self.dispatch_request()
  File "/Users/kadakia/anaconda3/lib/python3.6/site-packages/flask/app.py", line 1598, in dispatch_request
    return self.view_functions[rule.endpoint](**req.view_args)
  File "/Users/kadakia/anaconda3/lib/python3.6/site-packages/flask_login/utils.py", line 261, in decorated_view
    return func(*args, **kwargs)
  File "/Users/kadakia/flask_app/app/routes.py", line 32, in index
    next_url = next_url, prev_url = prev_url)
UnboundLocalError: local variable 'prev_url' referenced before assignment
2018-04-11 22:05:20,216 ERROR: Exception on /index [GET] [in /Users/kadakia/anaconda3/lib/python3.6/site-packages/flask/app.py:1560]
Traceback (most recent call last):
  File "/Users/kadakia/anaconda3/lib/python3.6/site-packages/flask/app.py", line 1982, in wsgi_app
    response = self.full_dispatch_request()
  File "/Users/kadakia/anaconda3/lib/python3.6/site-packages/flask/app.py", line 1614, in full_dispatch_request
    rv = self.handle_user_exception(e)
  File "/Users/kadakia/anaconda3/lib/python3.6/site-packages/flask/app.py", line 1517, in handle_user_exception
    reraise(exc_type, exc_value, tb)
  File "/Users/kadakia/anaconda3/lib/python3.6/site-packages/flask/_compat.py", line 33, in reraise
    raise value
  File "/Users/kadakia/anaconda3/lib/python3.6/site-packages/flask/app.py", line 1612, in full_dispatch_request
    rv = self.dispatch_request()
  File "/Users/kadakia/anaconda3/lib/python3.6/site-packages/flask/app.py", line 1598, in dispatch_request
    return self.view_functions[rule.endpoint](**req.view_args)
  File "/Users/kadakia/anaconda3/lib/python3.6/site-packages/flask_login/utils.py", line 261, in decorated_view
    return func(*args, **kwargs)
  File "/Users/kadakia/flask_app/app/routes.py", line 32, in index
    next_url = next_url, prev_url = prev_url)
UnboundLocalError: local variable 'prev_url' referenced before assignment
2018-04-11 22:05:41,834 INFO: RohanApp startup [in /Users/kadakia/flask_app/app/__init__.py:45]
2018-04-11 22:05:45,059 ERROR: Exception on /index [GET] [in /Users/kadakia/anaconda3/lib/python3.6/site-packages/flask/app.py:1560]
Traceback (most recent call last):
  File "/Users/kadakia/anaconda3/lib/python3.6/site-packages/flask/app.py", line 1982, in wsgi_app
    response = self.full_dispatch_request()
  File "/Users/kadakia/anaconda3/lib/python3.6/site-packages/flask/app.py", line 1614, in full_dispatch_request
    rv = self.handle_user_exception(e)
  File "/Users/kadakia/anaconda3/lib/python3.6/site-packages/flask/app.py", line 1517, in handle_user_exception
    reraise(exc_type, exc_value, tb)
  File "/Users/kadakia/anaconda3/lib/python3.6/site-packages/flask/_compat.py", line 33, in reraise
    raise value
  File "/Users/kadakia/anaconda3/lib/python3.6/site-packages/flask/app.py", line 1612, in full_dispatch_request
    rv = self.dispatch_request()
  File "/Users/kadakia/anaconda3/lib/python3.6/site-packages/flask/app.py", line 1598, in dispatch_request
    return self.view_functions[rule.endpoint](**req.view_args)
  File "/Users/kadakia/anaconda3/lib/python3.6/site-packages/flask_login/utils.py", line 261, in decorated_view
    return func(*args, **kwargs)
  File "/Users/kadakia/flask_app/app/routes.py", line 34, in index
    next_url = next_url, prev_url = prev_url)
UnboundLocalError: local variable 'prev_url' referenced before assignment
2018-04-11 22:05:51,157 ERROR: Exception on /index [GET] [in /Users/kadakia/anaconda3/lib/python3.6/site-packages/flask/app.py:1560]
Traceback (most recent call last):
  File "/Users/kadakia/anaconda3/lib/python3.6/site-packages/flask/app.py", line 1982, in wsgi_app
    response = self.full_dispatch_request()
  File "/Users/kadakia/anaconda3/lib/python3.6/site-packages/flask/app.py", line 1614, in full_dispatch_request
    rv = self.handle_user_exception(e)
  File "/Users/kadakia/anaconda3/lib/python3.6/site-packages/flask/app.py", line 1517, in handle_user_exception
    reraise(exc_type, exc_value, tb)
  File "/Users/kadakia/anaconda3/lib/python3.6/site-packages/flask/_compat.py", line 33, in reraise
    raise value
  File "/Users/kadakia/anaconda3/lib/python3.6/site-packages/flask/app.py", line 1612, in full_dispatch_request
    rv = self.dispatch_request()
  File "/Users/kadakia/anaconda3/lib/python3.6/site-packages/flask/app.py", line 1598, in dispatch_request
    return self.view_functions[rule.endpoint](**req.view_args)
  File "/Users/kadakia/anaconda3/lib/python3.6/site-packages/flask_login/utils.py", line 261, in decorated_view
    return func(*args, **kwargs)
  File "/Users/kadakia/flask_app/app/routes.py", line 34, in index
    next_url = next_url, prev_url = prev_url)
UnboundLocalError: local variable 'prev_url' referenced before assignment
2018-04-11 22:09:46,597 INFO: RohanApp startup [in /Users/kadakia/flask_app/app/__init__.py:45]
2018-04-11 22:10:24,477 INFO: RohanApp startup [in /Users/kadakia/flask_app/app/__init__.py:45]
2018-04-11 22:12:33,923 INFO: RohanApp startup [in /Users/kadakia/flask_app/app/__init__.py:45]
