2018-04-14 12:53:08,558 ERROR: Exception on /login [GET] [in /Users/kadakia/anaconda3/lib/python3.6/site-packages/flask/app.py:1560]
Traceback (most recent call last):
  File "/Users/kadakia/anaconda3/lib/python3.6/site-packages/flask/app.py", line 1982, in wsgi_app
    response = self.full_dispatch_request()
  File "/Users/kadakia/anaconda3/lib/python3.6/site-packages/flask/app.py", line 1614, in full_dispatch_request
    rv = self.handle_user_exception(e)
  File "/Users/kadakia/anaconda3/lib/python3.6/site-packages/flask/app.py", line 1517, in handle_user_exception
    reraise(exc_type, exc_value, tb)
  File "/Users/kadakia/anaconda3/lib/python3.6/site-packages/flask/_compat.py", line 33, in reraise
    raise value
  File "/Users/kadakia/anaconda3/lib/python3.6/site-packages/flask/app.py", line 1610, in full_dispatch_request
    rv = self.preprocess_request()
  File "/Users/kadakia/anaconda3/lib/python3.6/site-packages/flask/app.py", line 1831, in preprocess_request
    rv = func()
  File "/Users/kadakia/flask_app/app/routes.py", line 84, in before_request
    if current_user.is_authenticated:
  File "/Users/kadakia/anaconda3/lib/python3.6/site-packages/werkzeug/local.py", line 347, in __getattr__
    return getattr(self._get_current_object(), name)
  File "/Users/kadakia/anaconda3/lib/python3.6/site-packages/werkzeug/local.py", line 306, in _get_current_object
    return self.__local()
  File "/Users/kadakia/anaconda3/lib/python3.6/site-packages/flask_login/utils.py", line 26, in <lambda>
    current_user = LocalProxy(lambda: _get_user())
  File "/Users/kadakia/anaconda3/lib/python3.6/site-packages/flask_login/utils.py", line 335, in _get_user
    current_app.login_manager._load_user()
  File "/Users/kadakia/anaconda3/lib/python3.6/site-packages/flask_login/login_manager.py", line 359, in _load_user
    return self.reload_user()
  File "/Users/kadakia/anaconda3/lib/python3.6/site-packages/flask_login/login_manager.py", line 321, in reload_user
    user = self.user_callback(user_id)
  File "/Users/kadakia/flask_app/app/models.py", line 91, in load_user
    return User.query.get(int(id))
  File "/Users/kadakia/anaconda3/lib/python3.6/site-packages/sqlalchemy/orm/query.py", line 871, in get
    ident, loading.load_on_ident)
  File "/Users/kadakia/anaconda3/lib/python3.6/site-packages/sqlalchemy/orm/query.py", line 905, in _get_impl
    return fallback_fn(self, key)
  File "/Users/kadakia/anaconda3/lib/python3.6/site-packages/sqlalchemy/orm/loading.py", line 231, in load_on_ident
    return q.one()
  File "/Users/kadakia/anaconda3/lib/python3.6/site-packages/sqlalchemy/orm/query.py", line 2837, in one
    ret = self.one_or_none()
  File "/Users/kadakia/anaconda3/lib/python3.6/site-packages/sqlalchemy/orm/query.py", line 2807, in one_or_none
    ret = list(self)
  File "/Users/kadakia/anaconda3/lib/python3.6/site-packages/sqlalchemy/orm/loading.py", line 97, in instances
    util.raise_from_cause(err)
  File "/Users/kadakia/anaconda3/lib/python3.6/site-packages/sqlalchemy/util/compat.py", line 203, in raise_from_cause
    reraise(type(exception), exception, tb=exc_tb, cause=cause)
  File "/Users/kadakia/anaconda3/lib/python3.6/site-packages/sqlalchemy/util/compat.py", line 187, in reraise
    raise value
  File "/Users/kadakia/anaconda3/lib/python3.6/site-packages/sqlalchemy/orm/loading.py", line 78, in instances
    rows = [proc(row) for row in fetch]
  File "/Users/kadakia/anaconda3/lib/python3.6/site-packages/sqlalchemy/orm/loading.py", line 78, in <listcomp>
    rows = [proc(row) for row in fetch]
  File "/Users/kadakia/anaconda3/lib/python3.6/site-packages/sqlalchemy/orm/loading.py", line 492, in _instance
    loaded_instance, populate_existing, populators)
  File "/Users/kadakia/anaconda3/lib/python3.6/site-packages/sqlalchemy/orm/loading.py", line 592, in _populate_full
    dict_[key] = getter(row)
ValueError: Couldn't parse datetime string: '04/14/2018 04:06:17 PM'
2018-04-14 12:58:06,872 INFO: RohanApp startup [in /Users/kadakia/flask_app/app/__init__.py:51]
2018-04-14 13:01:32,507 INFO: RohanApp startup [in /Users/kadakia/flask_app/app/__init__.py:51]
2018-04-14 13:01:51,188 INFO: RohanApp startup [in /Users/kadakia/flask_app/app/__init__.py:51]
2018-04-14 13:02:07,257 INFO: RohanApp startup [in /Users/kadakia/flask_app/app/__init__.py:51]
2018-04-14 13:05:58,341 INFO: RohanApp startup [in /Users/kadakia/flask_app/app/__init__.py:51]
2018-04-14 13:11:46,913 INFO: RohanApp startup [in /Users/kadakia/flask_app/app/__init__.py:51]
2018-04-14 13:12:41,468 INFO: RohanApp startup [in /Users/kadakia/flask_app/app/__init__.py:51]
2018-04-14 13:13:25,310 ERROR: Exception on /explore [GET] [in /Users/kadakia/anaconda3/lib/python3.6/site-packages/flask/app.py:1560]
Traceback (most recent call last):
  File "/Users/kadakia/anaconda3/lib/python3.6/site-packages/flask/app.py", line 1982, in wsgi_app
    response = self.full_dispatch_request()
  File "/Users/kadakia/anaconda3/lib/python3.6/site-packages/flask/app.py", line 1614, in full_dispatch_request
    rv = self.handle_user_exception(e)
  File "/Users/kadakia/anaconda3/lib/python3.6/site-packages/flask/app.py", line 1517, in handle_user_exception
    reraise(exc_type, exc_value, tb)
  File "/Users/kadakia/anaconda3/lib/python3.6/site-packages/flask/_compat.py", line 33, in reraise
    raise value
  File "/Users/kadakia/anaconda3/lib/python3.6/site-packages/flask/app.py", line 1612, in full_dispatch_request
    rv = self.dispatch_request()
  File "/Users/kadakia/anaconda3/lib/python3.6/site-packages/flask/app.py", line 1598, in dispatch_request
    return self.view_functions[rule.endpoint](**req.view_args)
  File "/Users/kadakia/anaconda3/lib/python3.6/site-packages/flask_login/utils.py", line 261, in decorated_view
    return func(*args, **kwargs)
  File "/Users/kadakia/flask_app/app/routes.py", line 148, in explore
    return render_template('explore.html', title='Explore', posts=posts.items, next_url=next_url, prev_url=prev_url)
  File "/Users/kadakia/anaconda3/lib/python3.6/site-packages/flask/templating.py", line 134, in render_template
    context, ctx.app)
  File "/Users/kadakia/anaconda3/lib/python3.6/site-packages/flask/templating.py", line 116, in _render
    rv = template.render(context)
  File "/Users/kadakia/anaconda3/lib/python3.6/site-packages/jinja2/asyncsupport.py", line 76, in render
    return original_render(self, *args, **kwargs)
  File "/Users/kadakia/anaconda3/lib/python3.6/site-packages/jinja2/environment.py", line 1008, in render
    return self.environment.handle_exception(exc_info, True)
  File "/Users/kadakia/anaconda3/lib/python3.6/site-packages/jinja2/environment.py", line 780, in handle_exception
    reraise(exc_type, exc_value, tb)
  File "/Users/kadakia/anaconda3/lib/python3.6/site-packages/jinja2/_compat.py", line 37, in reraise
    raise value.with_traceback(tb)
  File "/Users/kadakia/flask_app/app/templates/explore.html", line 1, in top-level template code
    {% extends "base.html" %}
  File "/Users/kadakia/flask_app/app/templates/base.html", line 1, in top-level template code
    {% extends 'bootstrap/base.html' %}
  File "/Users/kadakia/anaconda3/lib/python3.6/site-packages/flask_bootstrap/templates/bootstrap/base.html", line 1, in top-level template code
    {% block doc -%}
  File "/Users/kadakia/anaconda3/lib/python3.6/site-packages/flask_bootstrap/templates/bootstrap/base.html", line 4, in block "doc"
    {%- block html %}
  File "/Users/kadakia/anaconda3/lib/python3.6/site-packages/flask_bootstrap/templates/bootstrap/base.html", line 20, in block "html"
    {% block body -%}
  File "/Users/kadakia/anaconda3/lib/python3.6/site-packages/flask_bootstrap/templates/bootstrap/base.html", line 23, in block "body"
    {% block content -%}
  File "/Users/kadakia/flask_app/app/templates/base.html", line 50, in block "content"
    {% block app_content %}{% endblock %}
  File "/Users/kadakia/flask_app/app/templates/explore.html", line 6, in block "app_content"
    {% include '_post.html' %}
  File "/Users/kadakia/flask_app/app/templates/_post.html", line 5, in top-level template code
    <img src="{{ post.author.avatar(70) }}" />
jinja2.exceptions.UndefinedError: 'None' has no attribute 'avatar'
