2018-04-14 13:14:08,777 ERROR: Exception on /explore [GET] [in /Users/kadakia/anaconda3/lib/python3.6/site-packages/flask/app.py:1560]
Traceback (most recent call last):
  File "/Users/kadakia/anaconda3/lib/python3.6/site-packages/flask/app.py", line 1982, in wsgi_app
    response = self.full_dispatch_request()
  File "/Users/kadakia/anaconda3/lib/python3.6/site-packages/flask/app.py", line 1614, in full_dispatch_request
    rv = self.handle_user_exception(e)
  File "/Users/kadakia/anaconda3/lib/python3.6/site-packages/flask/app.py", line 1517, in handle_user_exception
    reraise(exc_type, exc_value, tb)
  File "/Users/kadakia/anaconda3/lib/python3.6/site-packages/flask/_compat.py", line 33, in reraise
    raise value
  File "/Users/kadakia/anaconda3/lib/python3.6/site-packages/flask/app.py", line 1612, in full_dispatch_request
    rv = self.dispatch_request()
  File "/Users/kadakia/anaconda3/lib/python3.6/site-packages/flask/app.py", line 1598, in dispatch_request
    return self.view_functions[rule.endpoint](**req.view_args)
  File "/Users/kadakia/anaconda3/lib/python3.6/site-packages/flask_login/utils.py", line 261, in decorated_view
    return func(*args, **kwargs)
  File "/Users/kadakia/flask_app/app/routes.py", line 148, in explore
    return render_template('explore.html', title='Explore', posts=posts.items, next_url=next_url, prev_url=prev_url)
  File "/Users/kadakia/anaconda3/lib/python3.6/site-packages/flask/templating.py", line 134, in render_template
    context, ctx.app)
  File "/Users/kadakia/anaconda3/lib/python3.6/site-packages/flask/templating.py", line 116, in _render
    rv = template.render(context)
  File "/Users/kadakia/anaconda3/lib/python3.6/site-packages/jinja2/asyncsupport.py", line 76, in render
    return original_render(self, *args, **kwargs)
  File "/Users/kadakia/anaconda3/lib/python3.6/site-packages/jinja2/environment.py", line 1008, in render
    return self.environment.handle_exception(exc_info, True)
  File "/Users/kadakia/anaconda3/lib/python3.6/site-packages/jinja2/environment.py", line 780, in handle_exception
    reraise(exc_type, exc_value, tb)
  File "/Users/kadakia/anaconda3/lib/python3.6/site-packages/jinja2/_compat.py", line 37, in reraise
    raise value.with_traceback(tb)
  File "/Users/kadakia/flask_app/app/templates/explore.html", line 1, in top-level template code
    {% extends "base.html" %}
  File "/Users/kadakia/flask_app/app/templates/base.html", line 1, in top-level template code
    {% extends 'bootstrap/base.html' %}
  File "/Users/kadakia/anaconda3/lib/python3.6/site-packages/flask_bootstrap/templates/bootstrap/base.html", line 1, in top-level template code
    {% block doc -%}
  File "/Users/kadakia/anaconda3/lib/python3.6/site-packages/flask_bootstrap/templates/bootstrap/base.html", line 4, in block "doc"
    {%- block html %}
  File "/Users/kadakia/anaconda3/lib/python3.6/site-packages/flask_bootstrap/templates/bootstrap/base.html", line 20, in block "html"
    {% block body -%}
  File "/Users/kadakia/anaconda3/lib/python3.6/site-packages/flask_bootstrap/templates/bootstrap/base.html", line 23, in block "body"
    {% block content -%}
  File "/Users/kadakia/flask_app/app/templates/base.html", line 50, in block "content"
    {% block app_content %}{% endblock %}
  File "/Users/kadakia/flask_app/app/templates/explore.html", line 6, in block "app_content"
    {% include '_post.html' %}
  File "/Users/kadakia/flask_app/app/templates/_post.html", line 5, in top-level template code
    <img src="{{ post.author.avatar(70) }}" />
jinja2.exceptions.UndefinedError: 'None' has no attribute 'avatar'
2018-04-14 13:14:52,810 ERROR: Exception on /explore [GET] [in /Users/kadakia/anaconda3/lib/python3.6/site-packages/flask/app.py:1560]
Traceback (most recent call last):
  File "/Users/kadakia/anaconda3/lib/python3.6/site-packages/flask/app.py", line 1982, in wsgi_app
    response = self.full_dispatch_request()
  File "/Users/kadakia/anaconda3/lib/python3.6/site-packages/flask/app.py", line 1614, in full_dispatch_request
    rv = self.handle_user_exception(e)
  File "/Users/kadakia/anaconda3/lib/python3.6/site-packages/flask/app.py", line 1517, in handle_user_exception
    reraise(exc_type, exc_value, tb)
  File "/Users/kadakia/anaconda3/lib/python3.6/site-packages/flask/_compat.py", line 33, in reraise
    raise value
  File "/Users/kadakia/anaconda3/lib/python3.6/site-packages/flask/app.py", line 1612, in full_dispatch_request
    rv = self.dispatch_request()
  File "/Users/kadakia/anaconda3/lib/python3.6/site-packages/flask/app.py", line 1598, in dispatch_request
    return self.view_functions[rule.endpoint](**req.view_args)
  File "/Users/kadakia/anaconda3/lib/python3.6/site-packages/flask_login/utils.py", line 261, in decorated_view
    return func(*args, **kwargs)
  File "/Users/kadakia/flask_app/app/routes.py", line 148, in explore
    return render_template('explore.html', title='Explore', posts=posts.items, next_url=next_url, prev_url=prev_url)
  File "/Users/kadakia/anaconda3/lib/python3.6/site-packages/flask/templating.py", line 134, in render_template
    context, ctx.app)
  File "/Users/kadakia/anaconda3/lib/python3.6/site-packages/flask/templating.py", line 116, in _render
    rv = template.render(context)
  File "/Users/kadakia/anaconda3/lib/python3.6/site-packages/jinja2/asyncsupport.py", line 76, in render
    return original_render(self, *args, **kwargs)
  File "/Users/kadakia/anaconda3/lib/python3.6/site-packages/jinja2/environment.py", line 1008, in render
    return self.environment.handle_exception(exc_info, True)
  File "/Users/kadakia/anaconda3/lib/python3.6/site-packages/jinja2/environment.py", line 780, in handle_exception
    reraise(exc_type, exc_value, tb)
  File "/Users/kadakia/anaconda3/lib/python3.6/site-packages/jinja2/_compat.py", line 37, in reraise
    raise value.with_traceback(tb)
  File "/Users/kadakia/flask_app/app/templates/explore.html", line 1, in top-level template code
    {% extends "base.html" %}
  File "/Users/kadakia/flask_app/app/templates/base.html", line 1, in top-level template code
    {% extends 'bootstrap/base.html' %}
  File "/Users/kadakia/anaconda3/lib/python3.6/site-packages/flask_bootstrap/templates/bootstrap/base.html", line 1, in top-level template code
    {% block doc -%}
  File "/Users/kadakia/anaconda3/lib/python3.6/site-packages/flask_bootstrap/templates/bootstrap/base.html", line 4, in block "doc"
    {%- block html %}
  File "/Users/kadakia/anaconda3/lib/python3.6/site-packages/flask_bootstrap/templates/bootstrap/base.html", line 20, in block "html"
    {% block body -%}
  File "/Users/kadakia/anaconda3/lib/python3.6/site-packages/flask_bootstrap/templates/bootstrap/base.html", line 23, in block "body"
    {% block content -%}
  File "/Users/kadakia/flask_app/app/templates/base.html", line 50, in block "content"
    {% block app_content %}{% endblock %}
  File "/Users/kadakia/flask_app/app/templates/explore.html", line 6, in block "app_content"
    {% include '_post.html' %}
  File "/Users/kadakia/flask_app/app/templates/_post.html", line 5, in top-level template code
    <img src="{{ post.author.avatar(70) }}" />
jinja2.exceptions.UndefinedError: 'None' has no attribute 'avatar'
2018-04-14 13:15:47,874 INFO: RohanApp startup [in /Users/kadakia/flask_app/app/__init__.py:51]
2018-04-14 13:23:04,643 INFO: RohanApp startup [in /Users/kadakia/flask_app/app/__init__.py:51]
